Workbook

Sheet 🚀 시작하기
B1: 🚀 시작하기 — UAT 피드백 작성 가이드
B3: 안녕하세요! CTR HR Hub UAT 테스트에 참여해주셔서 감사합니다.
B4: 테스트 중 발견한 문제나 아이디어가 있으면 본 파일에 편하게 적어주세요.
B6: 📌 작성 원칙 한 줄: "다음 사람이 그대로 따라해서 재현할 수 있게 적어주세요."
B8: 1️⃣ 어떻게 사용하나요?
B9: • 화면 아래 탭(시트)에서 어떤 종류인지 고르고 → 한 줄(한 행)에 7개 칸을 채워주세요.
B10: 🔴 이건 잘 안돼요 — 문제·버그·오류·이상한 동작 신고
B11: 💡 이게 있으면 좋겠어요 — 새 기능·개선·편의성 제안
B12: • 한 건당 30초 안에 적고 다음 테스트로 돌아가세요. 너무 자세히 안 적어도 OK.
B13: • 스크린샷은 선택사항이지만, 가능하면 첨부해주시면 개발팀이 빨리 이해해요. (PrintScreen → 셀에 붙여넣기)
B14: • 같은 문제 여러 번 보였으면 새 줄 말고 비고에 횟수만 적어주세요.
B16: 2️⃣ 색깔·별점은 어떻게 정해요?
... B72: 💌 도움이 필요하면 언제든 UAT 관리자에게 직접 문의하세요. 완벽하게 안 적어도 괜찮습니다 — "있는 그대로" 적어주시는 게 가장 도움이 됩니다.

Sheet 🔴 이건 잘 안돼요
A1: 이름 | B1: 발견 날짜 | C1: 어느 화면에서? | D1: 무슨 일이 있었나요? | E1: 어떻게 됐으면 좋겠나요? | F1: 얼마나 불편한가요? | G1: 스크린샷 (선택)

Sheet 💡 이게 있으면 좋겠어요
A1: 이름 | B1: 작성 날짜 | C1: 어느 화면? | D1: 어떤 점이 아쉬워요? | E1: 어떻게 해주세요? | F1: 얼마나 도움이 될까요? | G1: 스크린샷 (선택)

Sheet 📊 관리자용 집계
A1: 📊 관리자용 집계 (UAT 관리자만 보세요)
A2: ⚠️ HR 테스터는 이 시트를 채울 필요가 없습니다. 다른 시트에 입력하시면 여기서 자동 집계됩니다.
A4: 1️⃣ 문제 신고 — 화면별 건수
A5: 화면 | B5: 🔴 일이 안 돼요 | C5: 🟡 불편하지만 우회 | D5: 🟢 사소 | E5: 합계
A6: 홈 / 알림 | B6: =COUNTIFS('🔴 이건 잘 안돼요'!C2:C51,A6,'🔴 이건 잘 안돼요'!F2:F51,"🔴 일이 안 돼요 (업무 불가능)") | C6: =COUNTIFS('🔴 이건 잘 안돼요'!C2:C51,A6,'🔴 이건 잘 안돼요'!F2:F51,"🟡 불편하지만 우회 가능") | D6: =COUNTIFS('🔴 이건 잘 안돼요'!C2:C51,A6,'🔴 이건 잘 안돼요'!F2:F51,"🟢 사소해요 (별 문제 없음)") | E6: =SUM(B6:D6)
A7: 나의 공간 (내 정보) | B7: =COUNTIFS('🔴 이건 잘 안돼요'!C2:C51,A7,'🔴 이건 잘 안돼요'!F2:F51,"🔴 일이 안 돼요 (업무 불가능)") | C7: =COUNTIFS('🔴 이건 잘 안돼요'!C2:C51,A7,'🔴 이건 잘 안돼요'!F2:F51,"🟡 불편하지만 우회 가능") | D7: =COUNTIFS('🔴 이건 잘 안돼요'!C2:C51,A7,'🔴 이건 잘 안돼요'!F2:F51,"🟢 사소해요 (별 문제 없음)") | E7: =SUM(B7:D7)
A8: 휴가 신청·조회 | B8: =COUNTIFS('🔴 이건 잘 안돼요'!C2:C51,A8,'🔴 이건 잘 안돼요'!F2:F51,"🔴 일이 안 돼요 (업무 불가능)") | C8: =COUNTIFS('🔴 이건 잘 안돼요'!C2:C51,A8,'🔴 이건 잘 안돼요'!F2:F51,"🟡 불편하지만 우회 가능") | D8: =COUNTIFS('🔴 이건 잘 안돼요'!C2:C51,A8,'🔴 이건 잘 안돼요'!F2:F51,"🟢 사소해요 (별 문제 없음)") | E8: =SUM(B8:D8)
A9: 휴직 신청·조회 | B9: =COUNTIFS('🔴 이건 잘 안돼요'!C2:C51,A9,'🔴 이건 잘 안돼요'!F2:F51,"🔴 일이 안 돼요 (업무 불가능)") | C9: =COUNTIFS('🔴 이건 잘 안돼요'!C2:C51,A9,'🔴 이건 잘 안돼요'!F2:F51,"🟡 불편하지만 우회 가능") | D9: =COUNTIFS('🔴 이건 잘 안돼요'!C2:C51,A9,'🔴 이건 잘 안돼요'!F2:F51,"🟢 사소해요 (별 문제 없음)") | E9: =SUM(B9:D9)
A10: 출퇴근 | B10: =COUNTIFS('🔴 이건 잘 안돼요'!C2:C51,A10,'🔴 이건 잘 안돼요'!F2:F51,"🔴 일이 안 돼요 (업무 불가능)") | C10: =COUNTIFS('🔴 이건 잘 안돼요'!C2:C51,A10,'🔴 이건 잘 안돼요'!F2:F51,"🟡 불편하지만 우회 가능") | D10: =COUNTIFS('🔴 이건 잘 안돼요'!C2:C51,A10,'🔴 이건 잘 안돼요'!F2:F51,"🟢 사소해요 (별 문제 없음)") | E10: =SUM(B10:D10)
A11: 결재함 (받은 결재) | B11: =COUNTIFS('🔴 이건 잘 안돼요'!C2:C51,A11,'🔴 이건 잘 안돼요'!F2:F51,"🔴 일이 안 돼요 (업무 불가능)") | C11: =COUNTIFS('🔴 이건 잘 안돼요'!C2:C51,A11,'🔴 이건 잘 안돼요'!F2:F51,"🟡 불편하지만 우회 가능") | D11: =COUNTIFS('🔴 이건 잘 안돼요'!C2:C51,A11,'🔴 이건 잘 안돼요'!F2:F51,"🟢 사소해요 (별 문제 없음)") | E11: =SUM(B11:D11)
A12: 내 결재 신청 내역 | B12: =COUNTIFS('🔴 이건 잘 안돼요'!C2:C51,A12,'🔴 이건 잘 안돼요'!F2:F51,"🔴 일이 안 돼요 (업무 불가능)") | C12: =COUNTIFS('🔴 이건 잘 안돼요'!C2:C51,A12,'🔴 이건 잘 안돼요'!F2:F51,"🟡 불편하지만 우회 가능") | D12: =COUNTIFS('🔴 이건 잘 안돼요'!C2:C51,A12,'🔴 이건 잘 안돼요'!F2:F51,"🟢 사소해요 (별 문제 없음)") | E12: =SUM(B12:D12)
A13: 급여명세서 | B13: =COUNTIFS('🔴 이건 잘 안돼요'!C2:C51,A13,'🔴 이건 잘 안돼요'!F2:F51,"🔴 일이 안 돼요 (업무 불가능)") | C13: =COUNTIFS('🔴 이건 잘 안돼요'!C2:C51,A13,'🔴 이건 잘 안돼요'!F2:F51,"🟡 불편하지만 우회 가능") | D13: =COUNTIFS('🔴 이건 잘 안돼요'!C2:C51,A13,'🔴 이건 잘 안돼요'!F2:F51,"🟢 사소해요 (별 문제 없음)") | E13: =SUM(B13:D13)
A14: 연말 정산 | B14: =COUNTIFS('🔴 이건 잘 안돼요'!C2:C51,A14,'🔴 이건 잘 안돼요'!F2:F51,"🔴 일이 안 돼요 (업무 불가능)") | C14: =COUNTIFS('🔴 이건 잘 안돼요'!C2:C51,A14,'🔴 이건 잘 안돼요'!F2:F51,"🟡 불편하지만 우회 가능") | D14: =COUNTIFS('🔴 이건 잘 안돼요'!C2:C51,A14,'🔴 이건 잘 안돼요'!F2:F51,"🟢 사소해요 (별 문제 없음)") | E14: =SUM(B14:D14)
A15: 내 목표·평가 | B15: =COUNTIFS('🔴 이건 잘 안돼요'!C2:C51,A15,'🔴 이건 잘 안돼요'!F2:F51,"🔴 일이 안 돼요 (업무 불가능)") | C15: =COUNTIFS('🔴 이건 잘 안돼요'!C2:C51,A15,'🔴 이건 잘 안돼요'!F2:F51,"🟡 불편하지만 우회 가능") | D15: =COUNTIFS('🔴 이건 잘 안돼요'!C2:C51,A15,'🔴 이건 잘 안돼요'!F2:F51,"🟢 사소해요 (별 문제 없음)") | E15: =SUM(B15:D15)
A16: 분기 리뷰 | B16: =COUNTIFS('🔴 이건 잘 안돼요'!C2:C51,A16,'🔴 이건 잘 안돼요'!F2:F51,"🔴 일이 안 돼요 (업무 불가능)") | C16: =COUNTIFS('🔴 이건 잘 안돼요'!C2:C51,A16,'🔴 이건 잘 안돼요'!F2:F51,"🟡 불편하지만 우회 가능") | D16: =COUNTIFS('🔴 이건 잘 안돼요'!C2:C51,A16,'🔴 이건 잘 안돼요'!F2:F51,"🟢 사소해요 (별 문제 없음)") | E16: =SUM(B16:D16)
A17: 인정·칭찬 | B17: =COUNTIFS('🔴 이건 잘 안돼요'!C2:C51,A17,'🔴 이건 잘 안돼요'!F2:F51,"🔴 일이 안 돼요 (업무 불가능)") | C17: =COUNTIFS('🔴 이건 잘 안돼요'!C2:C51,A17,'🔴 이건 잘 안돼요'!F2:F51,"🟡 불편하지만 우회 가능") | D17: =COUNTIFS('🔴 이건 잘 안돼요'!C2:C51,A17,'🔴 이건 잘 안돼요'!F2:F51,"🟢 사소해요 (별 문제 없음)") | E17: =SUM(B17:D17)
A18: 리포트·통계 | B18: =COUNTIFS('🔴 이건 잘 안돼요'!C2:C51,A18,'🔴 이건 잘 안돼요'!F2:F51,"🔴 일이 안 돼요 (업무 불가능)") | C18: =COUNTIFS('🔴 이건 잘 안돼요'!C2:C51,A18,'🔴 이건 잘 안돼요'!F2:F51,"🟡 불편하지만 우회 가능") | D18: =COUNTIFS('🔴 이건 잘 안돼요'!C2:C51,A18,'🔴 이건 잘 안돼요'!F2:F51,"🟢 사소해요 (별 문제 없음)") | E18: =SUM(B18:D18)
A19: 직원 관리 (HR) | B19: =COUNTIFS('🔴 이건 잘 안돼요'!C2:C51,A19,'🔴 이건 잘 안돼요'!F2:F51,"🔴 일이 안 돼요 (업무 불가능)") | C19: =COUNTIFS('🔴 이건 잘 안돼요'!C2:C51,A19,'🔴 이건 잘 안돼요'!F2:F51,"🟡 불편하지만 우회 가능") | D19: =COUNTIFS('🔴 이건 잘 안돼요'!C2:C51,A19,'🔴 이건 잘 안돼요'!F2:F51,"🟢 사소해요 (별 문제 없음)") | E19: =SUM(B19:D19)
A20: 조직도·부서 관리 (HR) | B20: =COUNTIFS('🔴 이건 잘 안돼요'!C2:C51,A20,'🔴 이건 잘 안돼요'!F2:F51,"🔴 일이 안 돼요 (업무 불가능)") | C20: =COUNTIFS('🔴 이건 잘 안돼요'!C2:C51,A20,'🔴 이건 잘 안돼요'!F2:F51,"🟡 불편하지만 우회 가능") | D20: =COUNTIFS('🔴 이건 잘 안돼요'!C2:C51,A20,'🔴 이건 잘 안돼요'!F2:F51,"🟢 사소해요 (별 문제 없음)") | E20: =SUM(B20:D20)
A21: 근태 관리 (HR) | B21: =COUNTIFS('🔴 이건 잘 안돼요'!C2:C51,A21,'🔴 이건 잘 안돼요'!F2:F51,"🔴 일이 안 돼요 (업무 불가능)") | C21: =COUNTIFS('🔴 이건 잘 안돼요'!C2:C51,A21,'🔴 이건 잘 안돼요'!F2:F51,"🟡 불편하지만 우회 가능") | D21: =COUNTIFS('🔴 이건 잘 안돼요'!C2:C51,A21,'🔴 이건 잘 안돼요'!F2:F51,"🟢 사소해요 (별 문제 없음)") | E21: =SUM(B21:D21)
A22: 휴가 관리 (HR) | B22: =COUNTIFS('🔴 이건 잘 안돼요'!C2:C51,A22,'🔴 이건 잘 안돼요'!F2:F51,"🔴 일이 안 돼요 (업무 불가능)") | C22: =COUNTIFS('🔴 이건 잘 안돼요'!C2:C51,A22,'🔴 이건 잘 안돼요'!F2:F51,"🟡 불편하지만 우회 가능") | D22: =COUNTIFS('🔴 이건 잘 안돼요'!C2:C51,A22,'🔴 이건 잘 안돼요'!F2:F51,"🟢 사소해요 (별 문제 없음)") | E22: =SUM(B22:D22)
A23: 급여 관리 (HR) | B23: =COUNTIFS('🔴 이건 잘 안돼요'!C2:C51,A23,'🔴 이건 잘 안돼요'!F2:F51,"🔴 일이 안 돼요 (업무 불가능)") | C23: =COUNTIFS('🔴 이건 잘 안돼요'!C2:C51,A23,'🔴 이건 잘 안돼요'!F2:F51,"🟡 불편하지만 우회 가능") | D23: =COUNTIFS('🔴 이건 잘 안돼요'!C2:C51,A23,'🔴 이건 잘 안돼요'!F2:F51,"🟢 사소해요 (별 문제 없음)") | E23: =SUM(B23:D23)
A24: 결재 흐름 설정 (HR) | B24: =COUNTIFS('🔴 이건 잘 안돼요'!C2:C51,A24,'🔴 이건 잘 안돼요'!F2:F51,"🔴 일이 안 돼요 (업무 불가능)") | C24: =COUNTIFS('🔴 이건 잘 안돼요'!C2:C51,A24,'🔴 이건 잘 안돼요'!F2:F51,"🟡 불편하지만 우회 가능") | D24: =COUNTIFS('🔴 이건 잘 안돼요'!C2:C51,A24,'🔴 이건 잘 안돼요'!F2:F51,"🟢 사소해요 (별 문제 없음)") | E24: =SUM(B24:D24)
A25: 채용 관리 (HR) | B25: =COUNTIFS('🔴 이건 잘 안돼요'!C2:C51,A25,'🔴 이건 잘 안돼요'!F2:F51,"🔴 일이 안 돼요 (업무 불가능)") | C25: =COUNTIFS('🔴 이건 잘 안돼요'!C2:C51,A25,'🔴 이건 잘 안돼요'!F2:F51,"🟡 불편하지만 우회 가능") | D25: =COUNTIFS('🔴 이건 잘 안돼요'!C2:C51,A25,'🔴 이건 잘 안돼요'!F2:F51,"🟢 사소해요 (별 문제 없음)") | E25: =SUM(B25:D25)
A26: 평가 관리 (HR) | B26: =COUNTIFS('🔴 이건 잘 안돼요'!C2:C51,A26,'🔴 이건 잘 안돼요'!F2:F51,"🔴 일이 안 돼요 (업무 불가능)") | C26: =COUNTIFS('🔴 이건 잘 안돼요'!C2:C51,A26,'🔴 이건 잘 안돼요'!F2:F51,"🟡 불편하지만 우회 가능") | D26: =COUNTIFS('🔴 이건 잘 안돼요'!C2:C51,A26,'🔴 이건 잘 안돼요'!F2:F51,"🟢 사소해요 (별 문제 없음)") | E26: =SUM(B26:D26)
A27: 보상 관리 (HR) | B27: =COUNTIFS('🔴 이건 잘 안돼요'!C2:C51,A27,'🔴 이건 잘 안돼요'!F2:F51,"🔴 일이 안 돼요 (업무 불가능)") | C27: =COUNTIFS('🔴 이건 잘 안돼요'!C2:C51,A27,'🔴 이건 잘 안돼요'!F2:F51,"🟡 불편하지만 우회 가능") | D27: =COUNTIFS('🔴 이건 잘 안돼요'!C2:C51,A27,'🔴 이건 잘 안돼요'!F2:F51,"🟢 사소해요 (별 문제 없음)") | E27: =SUM(B27:D27)
A28: 온보딩·오프보딩 (HR) | B28: =COUNTIFS('🔴 이건 잘 안돼요'!C2:C51,A28,'🔴 이건 잘 안돼요'!F2:F51,"🔴 일이 안 돼요 (업무 불가능)") | C28: =COUNTIFS('🔴 이건 잘 안돼요'!C2:C51,A28,'🔴 이건 잘 안돼요'!F2:F51,"🟡 불편하지만 우회 가능") | D28: =COUNTIFS('🔴 이건 잘 안돼요'!C2:C51,A28,'🔴 이건 잘 안돼요'!F2:F51,"🟢 사소해요 (별 문제 없음)") | E28: =SUM(B28:D28)
A29: 마스터데이터·설정 (HR) | B29: =COUNTIFS('🔴 이건 잘 안돼요'!C2:C51,A29,'🔴 이건 잘 안돼요'!F2:F51,"🔴 일이 안 돼요 (업무 불가능)") | C29: =COUNTIFS('🔴 이건 잘 안돼요'!C2:C51,A29,'🔴 이건 잘 안돼요'!F2:F51,"🟡 불편하지만 우회 가능") | D29: =COUNTIFS('🔴 이건 잘 안돼요'!C2:C51,A29,'🔴 이건 잘 안돼요'!F2:F51,"🟢 사소해요 (별 문제 없음)") | E29: =SUM(B29:D29)
A30: 컴플라이언스 (HR) | B30: =COUNTIFS('🔴 이건 잘 안돼요'!C2:C51,A30,'🔴 이건 잘 안돼요'!F2:F51,"🔴 일이 안 돼요 (업무 불가능)") | C30: =COUNTIFS('🔴 이건 잘 안돼요'!C2:C51,A30,'🔴 이건 잘 안돼요'!F2:F51,"🟡 불편하지만 우회 가능") | D30: =COUNTIFS('🔴 이건 잘 안돼요'!C2:C51,A30,'🔴 이건 잘 안돼요'!F2:F51,"🟢 사소해요 (별 문제 없음)") | E30: =SUM(B30:D30)
A31: 기타 | B31: =COUNTIFS('🔴 이건 잘 안돼요'!C2:C51,A31,'🔴 이건 잘 안돼요'!F2:F51,"🔴 일이 안 돼요 (업무 불가능)") | C31: =COUNTIFS('🔴 이건 잘 안돼요'!C2:C51,A31,'🔴 이건 잘 안돼요'!F2:F51,"🟡 불편하지만 우회 가능") | D31: =COUNTIFS('🔴 이건 잘 안돼요'!C2:C51,A31,'🔴 이건 잘 안돼요'!F2:F51,"🟢 사소해요 (별 문제 없음)") | E31: =SUM(B31:D31)
A32: 합계 | B32: =SUM(B6:B31) | C32: =SUM(C6:C31) | D32: =SUM(D6:D31) | E32: =SUM(E6:E31)
A35: 2️⃣ 개선 제안 — 화면별 건수
A36: 화면 | B36: ⭐⭐⭐ 매일 | C36: ⭐⭐ 가끔 | D36: ⭐ 있으면 좋음 | E36: 합계
A37: 홈 / 알림 | B37: =COUNTIFS('💡 이게 있으면 좋겠어요'!C2:C51,A37,'💡 이게 있으면 좋겠어요'!F2:F51,"⭐⭐⭐ 매일 도움이 될 거예요") | C37: =COUNTIFS('💡 이게 있으면 좋겠어요'!C2:C51,A37,'💡 이게 있으면 좋겠어요'!F2:F51,"⭐⭐ 가끔 도움이 될 거예요") | D37: =COUNTIFS('💡 이게 있으면 좋겠어요'!C2:C51,A37,'💡 이게 있으면 좋겠어요'!F2:F51,"⭐ 있으면 좋겠어요") | E37: =SUM(B37:D37)
A38: 나의 공간 (내 정보) | B38: =COUNTIFS('💡 이게 있으면 좋겠어요'!C2:C51,A38,'💡 이게 있으면 좋겠어요'!F2:F51,"⭐⭐⭐ 매일 도움이 될 거예요") | C38: =COUNTIFS('💡 이게 있으면 좋겠어요'!C2:C51,A38,'💡 이게 있으면 좋겠어요'!F2:F51,"⭐⭐ 가끔 도움이 될 거예요") | D38: =COUNTIFS('💡 이게 있으면 좋겠어요'!C2:C51,A38,'💡 이게 있으면 좋겠어요'!F2:F51,"⭐ 있으면 좋겠어요") | E38: =SUM(B38:D38)
A39: 휴가 신청·조회 | B39: =COUNTIFS('💡 이게 있으면 좋겠어요'!C2:C51,A39,'💡 이게 있으면 좋겠어요'!F2:F51,"⭐⭐⭐ 매일 도움이 될 거예요") | C39: =COUNTIFS('💡 이게 있으면 좋겠어요'!C2:C51,A39,'💡 이게 있으면 좋겠어요'!F2:F51,"⭐⭐ 가끔 도움이 될 거예요") | D39: =COUNTIFS('💡 이게 있으면 좋겠어요'!C2:C51,A39,'💡 이게 있으면 좋겠어요'!F2:F51,"⭐ 있으면 좋겠어요") | E39: =SUM(B39:D39)
A40: 휴직 신청·조회 | B40: =COUNTIFS('💡 이게 있으면 좋겠어요'!C2:C51,A40,'💡 이게 있으면 좋겠어요'!F2:F51,"⭐⭐⭐ 매일 도움이 될 거예요") | C40: =COUNTIFS('💡 이게 있으면 좋겠어요'!C2:C51,A40,'💡 이게 있으면 좋겠어요'!F2:F51,"⭐⭐ 가끔 도움이 될 거예요") | D40: =COUNTIFS('💡 이게 있으면 좋겠어요'!C2:C51,A40,'💡 이게 있으면 좋겠어요'!F2:F51,"⭐ 있으면 좋겠어요") | E40: =SUM(B40:D40)
A41: 출퇴근 | B41: =COUNTIFS('💡 이게 있으면 좋겠어요'!C2:C51,A41,'💡 이게 있으면 좋겠어요'!F2:F51,"⭐⭐⭐ 매일 도움이 될 거예요") | C41: =COUNTIFS('💡 이게 있으면 좋겠어요'!C2:C51,A41,'💡 이게 있으면 좋겠어요'!F2:F51,"⭐⭐ 가끔 도움이 될 거예요") | D41: =COUNTIFS('💡 이게 있으면 좋겠어요'!C2:C51,A41,'💡 이게 있으면 좋겠어요'!F2:F51,"⭐ 있으면 좋겠어요") | E41: =SUM(B41:D41)
A42: 결재함 (받은 결재) | B42: =COUNTIFS('💡 이게 있으면 좋겠어요'!C2:C51,A42,'💡 이게 있으면 좋겠어요'!F2:F51,"⭐⭐⭐ 매일 도움이 될 거예요") | C42: =COUNTIFS('💡 이게 있으면 좋겠어요'!C2:C51,A42,'💡 이게 있으면 좋겠어요'!F2:F51,"⭐⭐ 가끔 도움이 될 거예요") | D42: =COUNTIFS('💡 이게 있으면 좋겠어요'!C2:C51,A42,'💡 이게 있으면 좋겠어요'!F2:F51,"⭐ 있으면 좋겠어요") | E42: =SUM(B42:D42)
A43: 내 결재 신청 내역 | B43: =COUNTIFS('💡 이게 있으면 좋겠어요'!C2:C51,A43,'💡 이게 있으면 좋겠어요'!F2:F51,"⭐⭐⭐ 매일 도움이 될 거예요") | C43: =COUNTIFS('💡 이게 있으면 좋겠어요'!C2:C51,A43,'💡 이게 있으면 좋겠어요'!F2:F51,"⭐⭐ 가끔 도움이 될 거예요") | D43: =COUNTIFS('💡 이게 있으면 좋겠어요'!C2:C51,A43,'💡 이게 있으면 좋겠어요'!F2:F51,"⭐ 있으면 좋겠어요") | E43: =SUM(B43:D43)
...
