Workbook

Sheet 작성 안내
B1: UAT 피드백 작성 안내
B3: 1. 목적
B4: CTR HR Hub UAT(사용자 수용 테스트) 진행 중 발견하신 문제와 개선 제안을 기록하는 문서입니다.
B5: 본 폼에 입력하신 내용은 UAT 관리자가 매일 검토 후 개발팀에 정식 이슈로 전달합니다.
B7: 2. 시트 구성
B8: • 문제 보고 — 오류, 비정상 동작, 잘못된 결과 등을 보고합니다.
B9: • 개선 제안 — 신규 기능, 사용성 개선, 편의 기능 등을 제안합니다.
B10: • 집계 — UAT 관리자 전용입니다. 작성자는 입력하실 필요 없습니다.
B12: 3. 컬럼 작성 방법
B13: • 작성자: 본인 성함을 입력합니다.
B14: • 일자: 발견·작성 날짜 (YYYY-MM-DD).
B15: • 화면: 드롭다운에서 해당 화면을 선택합니다. 정확한 화면 명칭이 없으면 "기타"를 선택하고 비고에 보충 설명을 적어주세요.
... B71: 문의 사항은 UAT 관리자에게 직접 연락해주십시오. 작성 형식이 완벽하지 않아도 무방합니다. 관찰하신 사실을 그대로 기록해주시는 것이 가장 중요합니다.

Sheet 문제 보고
A1: 작성자 | B1: 발견 일자 | C1: 발생 화면 | D1: 발생 현상 | E1: 기대 결과 | F1: 심각도 | G1: 스크린샷 (권장)

Sheet 개선 제안
A1: 작성자 | B1: 작성 일자 | C1: 관련 화면 | D1: 현재 아쉬운 점 | E1: 제안 사항 | F1: 우선순위 | G1: 스크린샷 (권장)

Sheet 집계
A1: 집계 (UAT 관리자 전용)
A2: 작성자께서는 본 시트를 별도로 채우지 않으셔도 됩니다. 다른 시트 입력 시 자동 집계됩니다.
A4: 1. 문제 보고 — 화면별 건수
A5: 화면 | B5: 심각 | C5: 중요 | D5: 경미 | E5: 합계
A6: 홈 / 알림 | B6: =COUNTIFS('문제 보고'!C2:C51,A6,'문제 보고'!F2:F51,"심각 — 업무 진행 불가") | C6: =COUNTIFS('문제 보고'!C2:C51,A6,'문제 보고'!F2:F51,"중요 — 우회 가능") | D6: =COUNTIFS('문제 보고'!C2:C51,A6,'문제 보고'!F2:F51,"경미 — 사소한 표시 오류") | E6: =SUM(B6:D6)
A7: 나의 공간 (내 정보) | B7: =COUNTIFS('문제 보고'!C2:C51,A7,'문제 보고'!F2:F51,"심각 — 업무 진행 불가") | C7: =COUNTIFS('문제 보고'!C2:C51,A7,'문제 보고'!F2:F51,"중요 — 우회 가능") | D7: =COUNTIFS('문제 보고'!C2:C51,A7,'문제 보고'!F2:F51,"경미 — 사소한 표시 오류") | E7: =SUM(B7:D7)
A8: 휴가 신청·조회 | B8: =COUNTIFS('문제 보고'!C2:C51,A8,'문제 보고'!F2:F51,"심각 — 업무 진행 불가") | C8: =COUNTIFS('문제 보고'!C2:C51,A8,'문제 보고'!F2:F51,"중요 — 우회 가능") | D8: =COUNTIFS('문제 보고'!C2:C51,A8,'문제 보고'!F2:F51,"경미 — 사소한 표시 오류") | E8: =SUM(B8:D8)
A9: 휴직 신청·조회 | B9: =COUNTIFS('문제 보고'!C2:C51,A9,'문제 보고'!F2:F51,"심각 — 업무 진행 불가") | C9: =COUNTIFS('문제 보고'!C2:C51,A9,'문제 보고'!F2:F51,"중요 — 우회 가능") | D9: =COUNTIFS('문제 보고'!C2:C51,A9,'문제 보고'!F2:F51,"경미 — 사소한 표시 오류") | E9: =SUM(B9:D9)
A10: 출퇴근 | B10: =COUNTIFS('문제 보고'!C2:C51,A10,'문제 보고'!F2:F51,"심각 — 업무 진행 불가") | C10: =COUNTIFS('문제 보고'!C2:C51,A10,'문제 보고'!F2:F51,"중요 — 우회 가능") | D10: =COUNTIFS('문제 보고'!C2:C51,A10,'문제 보고'!F2:F51,"경미 — 사소한 표시 오류") | E10: =SUM(B10:D10)
A11: 결재함 (받은 결재) | B11: =COUNTIFS('문제 보고'!C2:C51,A11,'문제 보고'!F2:F51,"심각 — 업무 진행 불가") | C11: =COUNTIFS('문제 보고'!C2:C51,A11,'문제 보고'!F2:F51,"중요 — 우회 가능") | D11: =COUNTIFS('문제 보고'!C2:C51,A11,'문제 보고'!F2:F51,"경미 — 사소한 표시 오류") | E11: =SUM(B11:D11)
A12: 내 결재 신청 내역 | B12: =COUNTIFS('문제 보고'!C2:C51,A12,'문제 보고'!F2:F51,"심각 — 업무 진행 불가") | C12: =COUNTIFS('문제 보고'!C2:C51,A12,'문제 보고'!F2:F51,"중요 — 우회 가능") | D12: =COUNTIFS('문제 보고'!C2:C51,A12,'문제 보고'!F2:F51,"경미 — 사소한 표시 오류") | E12: =SUM(B12:D12)
A13: 급여명세서 | B13: =COUNTIFS('문제 보고'!C2:C51,A13,'문제 보고'!F2:F51,"심각 — 업무 진행 불가") | C13: =COUNTIFS('문제 보고'!C2:C51,A13,'문제 보고'!F2:F51,"중요 — 우회 가능") | D13: =COUNTIFS('문제 보고'!C2:C51,A13,'문제 보고'!F2:F51,"경미 — 사소한 표시 오류") | E13: =SUM(B13:D13)
A14: 연말 정산 | B14: =COUNTIFS('문제 보고'!C2:C51,A14,'문제 보고'!F2:F51,"심각 — 업무 진행 불가") | C14: =COUNTIFS('문제 보고'!C2:C51,A14,'문제 보고'!F2:F51,"중요 — 우회 가능") | D14: =COUNTIFS('문제 보고'!C2:C51,A14,'문제 보고'!F2:F51,"경미 — 사소한 표시 오류") | E14: =SUM(B14:D14)
A15: 내 목표·평가 | B15: =COUNTIFS('문제 보고'!C2:C51,A15,'문제 보고'!F2:F51,"심각 — 업무 진행 불가") | C15: =COUNTIFS('문제 보고'!C2:C51,A15,'문제 보고'!F2:F51,"중요 — 우회 가능") | D15: =COUNTIFS('문제 보고'!C2:C51,A15,'문제 보고'!F2:F51,"경미 — 사소한 표시 오류") | E15: =SUM(B15:D15)
A16: 분기 리뷰 | B16: =COUNTIFS('문제 보고'!C2:C51,A16,'문제 보고'!F2:F51,"심각 — 업무 진행 불가") | C16: =COUNTIFS('문제 보고'!C2:C51,A16,'문제 보고'!F2:F51,"중요 — 우회 가능") | D16: =COUNTIFS('문제 보고'!C2:C51,A16,'문제 보고'!F2:F51,"경미 — 사소한 표시 오류") | E16: =SUM(B16:D16)
A17: 인정·칭찬 | B17: =COUNTIFS('문제 보고'!C2:C51,A17,'문제 보고'!F2:F51,"심각 — 업무 진행 불가") | C17: =COUNTIFS('문제 보고'!C2:C51,A17,'문제 보고'!F2:F51,"중요 — 우회 가능") | D17: =COUNTIFS('문제 보고'!C2:C51,A17,'문제 보고'!F2:F51,"경미 — 사소한 표시 오류") | E17: =SUM(B17:D17)
A18: 리포트·통계 | B18: =COUNTIFS('문제 보고'!C2:C51,A18,'문제 보고'!F2:F51,"심각 — 업무 진행 불가") | C18: =COUNTIFS('문제 보고'!C2:C51,A18,'문제 보고'!F2:F51,"중요 — 우회 가능") | D18: =COUNTIFS('문제 보고'!C2:C51,A18,'문제 보고'!F2:F51,"경미 — 사소한 표시 오류") | E18: =SUM(B18:D18)
A19: 직원 관리 (HR) | B19: =COUNTIFS('문제 보고'!C2:C51,A19,'문제 보고'!F2:F51,"심각 — 업무 진행 불가") | C19: =COUNTIFS('문제 보고'!C2:C51,A19,'문제 보고'!F2:F51,"중요 — 우회 가능") | D19: =COUNTIFS('문제 보고'!C2:C51,A19,'문제 보고'!F2:F51,"경미 — 사소한 표시 오류") | E19: =SUM(B19:D19)
A20: 조직도·부서 관리 (HR) | B20: =COUNTIFS('문제 보고'!C2:C51,A20,'문제 보고'!F2:F51,"심각 — 업무 진행 불가") | C20: =COUNTIFS('문제 보고'!C2:C51,A20,'문제 보고'!F2:F51,"중요 — 우회 가능") | D20: =COUNTIFS('문제 보고'!C2:C51,A20,'문제 보고'!F2:F51,"경미 — 사소한 표시 오류") | E20: =SUM(B20:D20)
A21: 근태 관리 (HR) | B21: =COUNTIFS('문제 보고'!C2:C51,A21,'문제 보고'!F2:F51,"심각 — 업무 진행 불가") | C21: =COUNTIFS('문제 보고'!C2:C51,A21,'문제 보고'!F2:F51,"중요 — 우회 가능") | D21: =COUNTIFS('문제 보고'!C2:C51,A21,'문제 보고'!F2:F51,"경미 — 사소한 표시 오류") | E21: =SUM(B21:D21)
A22: 휴가 관리 (HR) | B22: =COUNTIFS('문제 보고'!C2:C51,A22,'문제 보고'!F2:F51,"심각 — 업무 진행 불가") | C22: =COUNTIFS('문제 보고'!C2:C51,A22,'문제 보고'!F2:F51,"중요 — 우회 가능") | D22: =COUNTIFS('문제 보고'!C2:C51,A22,'문제 보고'!F2:F51,"경미 — 사소한 표시 오류") | E22: =SUM(B22:D22)
A23: 급여 관리 (HR) | B23: =COUNTIFS('문제 보고'!C2:C51,A23,'문제 보고'!F2:F51,"심각 — 업무 진행 불가") | C23: =COUNTIFS('문제 보고'!C2:C51,A23,'문제 보고'!F2:F51,"중요 — 우회 가능") | D23: =COUNTIFS('문제 보고'!C2:C51,A23,'문제 보고'!F2:F51,"경미 — 사소한 표시 오류") | E23: =SUM(B23:D23)
A24: 결재 흐름 설정 (HR) | B24: =COUNTIFS('문제 보고'!C2:C51,A24,'문제 보고'!F2:F51,"심각 — 업무 진행 불가") | C24: =COUNTIFS('문제 보고'!C2:C51,A24,'문제 보고'!F2:F51,"중요 — 우회 가능") | D24: =COUNTIFS('문제 보고'!C2:C51,A24,'문제 보고'!F2:F51,"경미 — 사소한 표시 오류") | E24: =SUM(B24:D24)
A25: 채용 관리 (HR) | B25: =COUNTIFS('문제 보고'!C2:C51,A25,'문제 보고'!F2:F51,"심각 — 업무 진행 불가") | C25: =COUNTIFS('문제 보고'!C2:C51,A25,'문제 보고'!F2:F51,"중요 — 우회 가능") | D25: =COUNTIFS('문제 보고'!C2:C51,A25,'문제 보고'!F2:F51,"경미 — 사소한 표시 오류") | E25: =SUM(B25:D25)
A26: 평가 관리 (HR) | B26: =COUNTIFS('문제 보고'!C2:C51,A26,'문제 보고'!F2:F51,"심각 — 업무 진행 불가") | C26: =COUNTIFS('문제 보고'!C2:C51,A26,'문제 보고'!F2:F51,"중요 — 우회 가능") | D26: =COUNTIFS('문제 보고'!C2:C51,A26,'문제 보고'!F2:F51,"경미 — 사소한 표시 오류") | E26: =SUM(B26:D26)
A27: 보상 관리 (HR) | B27: =COUNTIFS('문제 보고'!C2:C51,A27,'문제 보고'!F2:F51,"심각 — 업무 진행 불가") | C27: =COUNTIFS('문제 보고'!C2:C51,A27,'문제 보고'!F2:F51,"중요 — 우회 가능") | D27: =COUNTIFS('문제 보고'!C2:C51,A27,'문제 보고'!F2:F51,"경미 — 사소한 표시 오류") | E27: =SUM(B27:D27)
A28: 온보딩·오프보딩 (HR) | B28: =COUNTIFS('문제 보고'!C2:C51,A28,'문제 보고'!F2:F51,"심각 — 업무 진행 불가") | C28: =COUNTIFS('문제 보고'!C2:C51,A28,'문제 보고'!F2:F51,"중요 — 우회 가능") | D28: =COUNTIFS('문제 보고'!C2:C51,A28,'문제 보고'!F2:F51,"경미 — 사소한 표시 오류") | E28: =SUM(B28:D28)
A29: 마스터데이터·설정 (HR) | B29: =COUNTIFS('문제 보고'!C2:C51,A29,'문제 보고'!F2:F51,"심각 — 업무 진행 불가") | C29: =COUNTIFS('문제 보고'!C2:C51,A29,'문제 보고'!F2:F51,"중요 — 우회 가능") | D29: =COUNTIFS('문제 보고'!C2:C51,A29,'문제 보고'!F2:F51,"경미 — 사소한 표시 오류") | E29: =SUM(B29:D29)
A30: 컴플라이언스 (HR) | B30: =COUNTIFS('문제 보고'!C2:C51,A30,'문제 보고'!F2:F51,"심각 — 업무 진행 불가") | C30: =COUNTIFS('문제 보고'!C2:C51,A30,'문제 보고'!F2:F51,"중요 — 우회 가능") | D30: =COUNTIFS('문제 보고'!C2:C51,A30,'문제 보고'!F2:F51,"경미 — 사소한 표시 오류") | E30: =SUM(B30:D30)
A31: 기타 | B31: =COUNTIFS('문제 보고'!C2:C51,A31,'문제 보고'!F2:F51,"심각 — 업무 진행 불가") | C31: =COUNTIFS('문제 보고'!C2:C51,A31,'문제 보고'!F2:F51,"중요 — 우회 가능") | D31: =COUNTIFS('문제 보고'!C2:C51,A31,'문제 보고'!F2:F51,"경미 — 사소한 표시 오류") | E31: =SUM(B31:D31)
A32: 합계 | B32: =SUM(B6:B31) | C32: =SUM(C6:C31) | D32: =SUM(D6:D31) | E32: =SUM(E6:E31)
A35: 2. 개선 제안 — 화면별 건수
A36: 화면 | B36: 높음 | C36: 중간 | D36: 낮음 | E36: 합계
A37: 홈 / 알림 | B37: =COUNTIFS('개선 제안'!C2:C51,A37,'개선 제안'!F2:F51,"높음 — 매일 활용 예상") | C37: =COUNTIFS('개선 제안'!C2:C51,A37,'개선 제안'!F2:F51,"중간 — 주 1~2회 활용") | D37: =COUNTIFS('개선 제안'!C2:C51,A37,'개선 제안'!F2:F51,"낮음 — 가끔 활용") | E37: =SUM(B37:D37)
A38: 나의 공간 (내 정보) | B38: =COUNTIFS('개선 제안'!C2:C51,A38,'개선 제안'!F2:F51,"높음 — 매일 활용 예상") | C38: =COUNTIFS('개선 제안'!C2:C51,A38,'개선 제안'!F2:F51,"중간 — 주 1~2회 활용") | D38: =COUNTIFS('개선 제안'!C2:C51,A38,'개선 제안'!F2:F51,"낮음 — 가끔 활용") | E38: =SUM(B38:D38)
A39: 휴가 신청·조회 | B39: =COUNTIFS('개선 제안'!C2:C51,A39,'개선 제안'!F2:F51,"높음 — 매일 활용 예상") | C39: =COUNTIFS('개선 제안'!C2:C51,A39,'개선 제안'!F2:F51,"중간 — 주 1~2회 활용") | D39: =COUNTIFS('개선 제안'!C2:C51,A39,'개선 제안'!F2:F51,"낮음 — 가끔 활용") | E39: =SUM(B39:D39)
A40: 휴직 신청·조회 | B40: =COUNTIFS('개선 제안'!C2:C51,A40,'개선 제안'!F2:F51,"높음 — 매일 활용 예상") | C40: =COUNTIFS('개선 제안'!C2:C51,A40,'개선 제안'!F2:F51,"중간 — 주 1~2회 활용") | D40: =COUNTIFS('개선 제안'!C2:C51,A40,'개선 제안'!F2:F51,"낮음 — 가끔 활용") | E40: =SUM(B40:D40)
A41: 출퇴근 | B41: =COUNTIFS('개선 제안'!C2:C51,A41,'개선 제안'!F2:F51,"높음 — 매일 활용 예상") | C41: =COUNTIFS('개선 제안'!C2:C51,A41,'개선 제안'!F2:F51,"중간 — 주 1~2회 활용") | D41: =COUNTIFS('개선 제안'!C2:C51,A41,'개선 제안'!F2:F51,"낮음 — 가끔 활용") | E41: =SUM(B41:D41)
A42: 결재함 (받은 결재) | B42: =COUNTIFS('개선 제안'!C2:C51,A42,'개선 제안'!F2:F51,"높음 — 매일 활용 예상") | C42: =COUNTIFS('개선 제안'!C2:C51,A42,'개선 제안'!F2:F51,"중간 — 주 1~2회 활용") | D42: =COUNTIFS('개선 제안'!C2:C51,A42,'개선 제안'!F2:F51,"낮음 — 가끔 활용") | E42: =SUM(B42:D42)
A43: 내 결재 신청 내역 | B43: =COUNTIFS('개선 제안'!C2:C51,A43,'개선 제안'!F2:F51,"높음 — 매일 활용 예상") | C43: =COUNTIFS('개선 제안'!C2:C51,A43,'개선 제안'!F2:F51,"중간 — 주 1~2회 활용") | D43: =COUNTIFS('개선 제안'!C2:C51,A43,'개선 제안'!F2:F51,"낮음 — 가끔 활용") | E43: =SUM(B43:D43)
...
